Workbook

Sheet SAP Timeline
A1: APM - SAP Activity & Support Plan | SAP Timeline (Weekly)
A2: SAP schedule view for SAP-only stakeholders - read-only: dates/status LINK from the 'APM Plan & FTE' tab (edit them there, this view updates automatically) | orange header + gray band = current week; red block = Go-Live week | AS OF 27 AUG 2026 - SAP Go-Live 1 Jul 2027
A3: Phase: | B3: A | C3: B | D3: C | E3: D | F3: E | H3: No required info
I4: Feb | J4: Mar | O4: Apr | S4: May | W4: Jun | AB4: Jul | AF4: Aug | AK4: Sep | AO4: Oct | AS4: Nov | AX4: Dec | BB4: Jan 27 | BF4: Feb | BJ4: Mar | BO4: Apr | BS4: May | BX4: Jun | CB4: Jul | CF4: Aug | CK4: Sep | CO4: Oct | CS4: Nov | CX4: Dec
A5: # | B5: Key Activities & Scope | C5: Status | D5: SAP Start | E5: SAP End | F5: Dur (d) | G5: Mock Readiness | H5: Remark | I5: 46076 | J5: 46083 | K5: 46090 | L5: 46097 | M5: 46104 | N5: 46111 | O5: 46118 | P5: 46125 | Q5: 46132 | R5: 46139 | S5: 46146 | T5: 46153 | U5: 46160 | V5: 46167 | W5: 46174 | X5: 46181 | Y5: 46188 | Z5: 46195 | AA5: 46202 | AB5: 46209 | AC5: 46216 | AD5: 46223 | AE5: 46230 | AF5: 46237 | AG5: 46244 | AH5: 46251 | AI5: 46258 | AJ5: 46265 | AK5: 46272 | AL5: 46279 | AM5: 46286 | AN5: 46293 | AO5: 46300 | AP5: 46307 | AQ5: 46314 | AR5: 46321 | AS5: 46328 | AT5: 46335 | AU5: 46342 | AV5: 46349 | AW5: 46356 | AX5: 46363 | AY5: 46370 | AZ5: 46377 | BA5: 46384 | BB5: 46391 | BC5: 46398 | BD5: 46405 | BE5: 46412 | BF5: 46419 | BG5: 46426 | BH5: 46433 | BI5: 46440 | BJ5: 46447 | BK5: 46454 | BL5: 46461 | BM5: 46468 | BN5: 46475 | BO5: 46482 | BP5: 46489 | BQ5: 46496 | BR5: 46503 | BS5: 46510 | BT5: 46517 | BU5: 46524 | BV5: 46531 | BW5: 46538 | BX5: 46545 | BY5: 46552 | BZ5: 46559 | CA5: 46566 | CB5: 46573 | CC5: 46580 | CD5: 46587 | CE5: 46594 | CF5: 46601 | CG5: 46608 | CH5: 46615 | CI5: 46622 | CJ5: 46629 | CK5: 46636 | CL5: 46643 | CM5: 46650 | CN5: 46657 | CO5: 46664 | CP5: 46671 | CQ5: 46678 | CR5: 46685 | CS5: 46692 | CT5: 46699 | CU5: 46706 | CV5: 46713 | CW5: 46720 | CX5: 46727 | CY5: 46734 | CZ5: 46741 | DA5: 46748
A6: A.Impact Analysis — impact assessment and mapping
A7: 1 | B7: Risk, action, issue tracking | C7: ='APM Plan & FTE'!C7 -> In progress | D7: ='APM Plan & FTE'!D7 -> 46113 | E7: ='APM Plan & FTE'!E7 -> 46660 | F7: =IF(AND(ISNUMBER($D7),ISNUMBER($E7)),$E7-$D7+1,"") -> 548 | H7: + Monitor all project life cycle
A8: B.Testing Support — for Accenture (ACN) and End Users
A9: 2 | B9: CIT | C9: ='APM Plan & FTE'!C10 -> In progress | D9: ='APM Plan & FTE'!D10 -> 46288 | E9: ='APM Plan & FTE'!E10 -> 46293 | F9: =IF(AND(ISNUMBER($D9),ISNUMBER($E9)),$E9-$D9+1,"") -> 6 | H9: + Depending on cr, currently approved and done cr 15 Sep 2026 | PM-I-109 (APM - SAP) under JIRA SHANA-168749
A10: 3 | B10: SIT (mc1) | C10: ='APM Plan & FTE'!C12 -> Not started | D10: ='APM Plan & FTE'!D12 -> 46296 | E10: ='APM Plan & FTE'!E12 -> 46376 | F10: =IF(AND(ISNUMBER($D10),ISNUMBER($E10)),$E10-$D10+1,"") -> 81 | H10: + Waiting for confirmation date from SHANA + Waiting for revised test case from SHANA + Depending on CIT and ACN fixed FD look like
A11: 4 | B11: UAT (mc2) | C11: ='APM Plan & FTE'!C14 -> Not started | D11: ='APM Plan & FTE'!D14 -> 46391 | E11: ='APM Plan & FTE'!E14 -> 46461 | F11: =IF(AND(ISNUMBER($D11),ISNUMBER($E11)),$E11-$D11+1,"") -> 71 | H11: + Wait for confirmation date from SHANA
A12: 5 | B12: Business Simulation (mc3) | C12: ='APM Plan & FTE'!C16 -> Not started | D12: ='APM Plan & FTE'!D16 -> 46466 | E12: ='APM Plan & FTE'!E16 -> 46507 | F12: =IF(AND(ISNUMBER($D12),ISNUMBER($E12)),$E12-$D12+1,"") -> 42 | H12: + Wait for confirmation date from SHANA
A13: C.Mock Validation — align with S/4HANA by switch source appoach
A14: 6 | B14: Mock 1 Execution (SIT) | C14: ='APM Plan & FTE'!C19 -> Completed | D14: ='APM Plan & FTE'!D19 -> 46113 | E14: ='APM Plan & FTE'!E19 -> 46203 | F14: =IF(AND(ISNUMBER($D14),ISNUMBER($E14)),$E14-$D14+1,"") -> 91 | G14: 46143 | H14: + Already validated and done
A15: 7 | B15: Mock 2 Execution (UAT) | C15: ='APM Plan & FTE'!C21 -> Not started | D15: ='APM Plan & FTE'!D21 -> 46113 | E15: ='APM Plan & FTE'!E21 -> 46356 | F15: =IF(AND(ISNUMBER($D15),ISNUMBER($E15)),$E15-$D15+1,"") -> 244 | G15: 46286 | H15: + Post load to GCP 21 Sep 2026 + Required another 2 weeks (10 working days) for GCP team to prepares data
A16: 8 | B16: Mock 3 Execution/FDR | C16: ='APM Plan & FTE'!C23 -> Not started | D16: ='APM Plan & FTE'!D23 -> 46357 | E16: ='APM Plan & FTE'!E23 -> 46477 | F16: =IF(AND(ISNUMBER($D16),ISNUMBER($E16)),$E16-$D16+1,"") -> 121 | G16: TBC | H16: + Wait for confirmation date from SHANA
A17: D.Cutover & Go-Live — prep and alignment with end users
A18: 9 | B18: Ramp Down (ACO) | C18: ='APM Plan & FTE'!C26 -> Not started | D18: ='APM Plan & FTE'!D26 -> 46510 | E18: ='APM Plan & FTE'!E26 -> 46563 | F18: =IF(AND(ISNUMBER($D18),ISNUMBER($E18)),$E18-$D18+1,"") -> 54
A19: 10 | B19: Blackout Period: Deploy APM to Production (DB, BE, FE) | C19: ='APM Plan & FTE'!C28 -> Not started | D19: ='APM Plan & FTE'!D28 -> 46564 | E19: ='APM Plan & FTE'!E28 -> 46568 | F19: =IF(AND(ISNUMBER($D19),ISNUMBER($E19)),$E19-$D19+1,"") -> 5 | H19: + SAP Go-Live, 1 Jul 2027
A20: 11 | B20: Ramp Up | C20: ='APM Plan & FTE'!C30 -> Not started | D20: ='APM Plan & FTE'!D30 -> 46569 | E20: ='APM Plan & FTE'!E30 -> 46599 | F20: =IF(AND(ISNUMBER($D20),ISNUMBER($E20)),$E20-$D20+1,"") -> 31 | H20: + After Go-Live
A21: E.Training & Post Go-Live — hypercare support & monitoring
A22: 12 | B22: Hypercare support operations & incident management | C22: ='APM Plan & FTE'!C33 -> Not started | D22: ='APM Plan & FTE'!D33 -> TBC | E22: ='APM Plan & FTE'!E33 -> 0 | F22: =IF(AND(ISNUMBER($D22),ISNUMBER($E22)),$E22-$D22+1,"") | H22: + Plan: Jul–Sep 2027 (PGLS phase)
A23: SAP Go-Live (Milestone) | D23: ='APM Plan & FTE'!D35 -> 46569
A25: Notes:
A26: 1. READ-ONLY SAP schedule view. Dates, status and the Go-Live date are linked formulas from the 'APM Plan & FTE' tab - edit them there, this view updates automatically.
A27: 2. One row per activity = the SAP window (phase color). APM's own dates and FTE planning live on the 'APM Plan & FTE' tab.
A28: 3. Many dates are TBC - waiting for confirmation from SHANA (SIT, UAT, Business Sim, Mock 3, Ramp Down, Blackout, Ramp Up, Hypercare).
A29: 4. Orange header + gray band = current week; red block = SAP Go-Live week (1 Jul 2027).

Sheet APM Plan & FTE
A1: APM - SAP Activity & Support Plan | Gantt (Weekly) + FTE Tracking
A2: Two stacked bars per activity: phase color = SAP window (SAP Start/End D:E); blue = APM's own window (APM Start/End F:G; red TBC = not confirmed yet) | Edit dates/Status/FTE here - bars, Dur and FTE shading update automatically | FTE grid below: role rows x weeks, values inside each activity's APM window | orange header + gray band = current week; red block = Go-Live week | AS OF 27 AUG 2026 - SAP Go-Live 1 Jul 2027
A3: Phase: | B3: A | C3: B | D3: C | E3: D | F3: E | I3: APM own window (cols F-G)
K4: Feb | L4: Mar | Q4: Apr | U4: May | Y4: Jun | AD4: Jul | AH4: Aug | AM4: Sep | AQ4: Oct | AU4: Nov | AZ4: Dec | BD4: Jan 27 | BH4: Feb | BL4: Mar | BQ4: Apr | BU4: May | BZ4: Jun | CD4: Jul | CH4: Aug | CM4: Sep | CQ4: Oct | CU4: Nov | CZ4: Dec
A5: # | B5: Key Activities & Scope | C5: Status | D5: SAP Start | E5: SAP End | F5: APM Start | G5: APM End | H5: Dur (d) | I5: Mock Readiness | J5: Remark | K5: 46076 | L5: 46083 | M5: 46090 | N5: 46097 | O5: 46104 | P5: 46111 | Q5: 46118 | R5: 46125 | S5: 46132 | T5: 46139 | U5: 46146 | V5: 46153 | W5: 46160 | X5: 46167 | Y5: 46174 | Z5: 46181 | AA5: 46188 | AB5: 46195 | AC5: 46202 | AD5: 46209 | AE5: 46216 | AF5: 46223 | AG5: 46230 | AH5: 46237 | AI5: 46244 | AJ5: 46251 | AK5: 46258 | AL5: 46265 | AM5: 46272 | AN5: 46279 | AO5: 46286 | AP5: 46293 | AQ5: 46300 | AR5: 46307 | AS5: 46314 | AT5: 46321 | AU5: 46328 | AV5: 46335 | AW5: 46342 | AX5: 46349 | AY5: 46356 | AZ5: 46363 | BA5: 46370 | BB5: 46377 | BC5: 46384 | BD5: 46391 | BE5: 46398 | BF5: 46405 | BG5: 46412 | BH5: 46419 | BI5: 46426 | BJ5: 46433 | BK5: 46440 | BL5: 46447 | BM5: 46454 | BN5: 46461 | BO5: 46468 | BP5: 46475 | BQ5: 46482 | BR5: 46489 | BS5: 46496 | BT5: 46503 | BU5: 46510 | BV5: 46517 | BW5: 46524 | BX5: 46531 | BY5: 46538 | BZ5: 46545 | CA5: 46552 | CB5: 46559 | CC5: 46566 | CD5: 46573 | CE5: 46580 | CF5: 46587 | CG5: 46594 | CH5: 46601 | CI5: 46608 | CJ5: 46615 | CK5: 46622 | CL5: 46629 | CM5: 46636 | CN5: 46643 | CO5: 46650 | CP5: 46657 | CQ5: 46664 | CR5: 46671 | CS5: 46678 | CT5: 46685 | CU5: 46692 | CV5: 46699 | CW5: 46706 | CX5: 46713 | CY5: 46720 | CZ5: 46727 | DA5: 46734 | DB5: 46741 | DC5: 46748
A6: A.Impact Analysis — impact assessment and mapping
A7: 1 | B7: Risk, action, issue tracking | C7: In progress | D7: 46113 | E7: 46660 | H7: =IF(AND(ISNUMBER($D7),ISNUMBER($E7)),$E7-$D7+1,"") -> 548 | J7: + Monitor all project life cycle
F8: 46113 | G8: 46660
A9: B.Testing Support — for Accenture (ACN) and End Users
A10: 2 | B10: CIT | C10: In progress | D10: 46288 | E10: 46293 | H10: =IF(AND(ISNUMBER($D10),ISNUMBER($E10)),$E10-$D10+1,"") -> 6 | J10: + Depending on cr, currently approved and done cr 15 Sep 2026 | PM-I-109 (APM - SAP) under JIRA SHANA-168749
F11: 46288 | G11: 46293
A12: 3 | B12: SIT (mc1) | C12: Not started | D12: 46296 | E12: 46376 | H12: =IF(AND(ISNUMBER($D12),ISNUMBER($E12)),$E12-$D12+1,"") -> 81 | J12: + Waiting for confirmation date from SHANA + Waiting for revised test case from SHANA + Depending on CIT and ACN fixed FD look like
F13: TBC
A14: 4 | B14: UAT (mc2) | C14: Not started | D14: 46391 | E14: 46461 | H14: =IF(AND(ISNUMBER($D14),ISNUMBER($E14)),$E14-$D14+1,"") -> 71 | J14: + Wait for confirmation date from SHANA
F15: TBC
A16: 5 | B16: Business Simulation (mc3) | C16: Not started | D16: 46466 | E16: 46507 | H16: =IF(AND(ISNUMBER($D16),ISNUMBER($E16)),$E16-$D16+1,"") -> 42 | J16: + Wait for confirmation date from SHANA
F17: TBC
A18: C.Mock Validation — align with S/4HANA by switch source appoach
A19: 6 | B19: Mock 1 Execution (SIT) | C19: Completed | D19: 46113 | E19: 46203 | H19: =IF(AND(ISNUMBER($D19),ISNUMBER($E19)),$E19-$D19+1,"") -> 91 | I19: 46143 | J19: + Already validated and done
F20: TBC
A21: 7 | B21: Mock 2 Execution (UAT) | C21: Not started | D21: 46113 | E21: 46356 | H21: =IF(AND(ISNUMBER($D21),ISNUMBER($E21)),$E21-$D21+1,"") -> 244 | I21: 46286 | J21: + Post load to GCP 21 Sep 2026 + Required another 2 weeks (10 working days) for GCP team to prepares data
F22: 46304 | G22: 46304
A23: 8 | B23: Mock 3 Execution/FDR | C23: Not started | D23: 46357 | E23: 46477 | H23: =IF(AND(ISNUMBER($D23),ISNUMBER($E23)),$E23-$D23+1,"") -> 121 | I23: TBC | J23: + Wait for confirmation date from SHANA
F24: TBC
A25: D.Cutover & Go-Live — prep and alignment with end users
A26: 9 | B26: Ramp Down (ACO) | C26: Not started | D26: 46510 | E26: 46563 | H26: =IF(AND(ISNUMBER($D26),ISNUMBER($E26)),$E26-$D26+1,"") -> 54
F27: TBC
A28: 10 | B28: Blackout Period: Deploy APM to Production (DB, BE, FE) | C28: Not started | D28: 46564 | E28: 46568 | H28: =IF(AND(ISNUMBER($D28),ISNUMBER($E28)),$E28-$D28+1,"") -> 5 | J28: + SAP Go-Live, 1 Jul 2027
F29: TBC
A30: 11 | B30: Ramp Up | C30: Not started | D30: 46569 | E30: 46599 | H30: =IF(AND(ISNUMBER($D30),ISNUMBER($E30)),$E30-$D30+1,"") -> 31 | J30: + After Go-Live
F31: TBC
A32: E.Training & Post Go-Live — hypercare support & monitoring
A33: 12 | B33: Hypercare support operations & incident management | C33: Not started | D33: TBC | H33: =IF(AND(ISNUMBER($D33),ISNUMBER($E33)),$E33-$D33+1,"") | J33: + Plan: Jul–Sep 2027 (PGLS phase)
F34: TBC
A35: SAP Go-Live (Milestone) | D35: 46569
A37: FTE TRACKING - monthly FTE by position (Feb'26 to Dec'27)
A38: 1.0 = one person for the full month. One row per person (position repeated per person). Values are MOCK SAMPLES - type over them. The 'Total FTE' row auto-sums each month.
B39: Position | K39: Feb'26 | L39: Mar'26 | Q39: Apr'26 | U39: May'26 | Y39: Jun'26 | AD39: Jul'26 | AH39: Aug'26 | AM39: Sep'26 | AQ39: Oct'26 | AU39: Nov'26 | AZ39: Dec'26 | BD39: Jan'27 | BH39: Feb'27 | BL39: Mar'27 | BQ39: Apr'27 | BU39: May'27 | BZ39: Jun'27 | CD39: Jul'27 | CH39: Aug'27 | CM39: Sep'27 | CQ39: Oct'27 | CU39: Nov'27 | CZ39: Dec'27
B40: ITPM | K40: 0 | L40: 0 | Q40: 0.2 | U40: 0.1 | Y40: 0.11 | AD40: 0.11 | AH40: 0.1 | AM40: 0.2 | AQ40: 0.2 | AU40: 0.2 | AZ40: 0.2 | BD40: 0.2 | BH40: 0.1 | BL40: 0.11 | BQ40: 0.11 | BU40: 0.1 | BZ40: 0.2 | CD40: 0.2 | CH40: 0.2 | CM40: 0.2 | CQ40: 0 | CU40: 0 | CZ40: 0
B41: Scrum Master | K41: 0 | L41: 0 | Q41: 0.4 | U41: 0.4 | Y41: 0.4 | AD41: 0.4 | AH41: 0.4 | AM41: 0.4 | AQ41: 0.4 | AU41: 0.4 | AZ41: 0.4 | BD41: 0.4 | BH41: 0.4 | BL41: 0.4 | BQ41: 0.4 | BU41: 0.4 | BZ41: 0.4 | CD41: 0.4 | CH41: 0.4 | CM41: 0.4 | CQ41: 0 | CU41: 0 | CZ41: 0
...
